Traceback (most recent call last):
  File "C:\Users\Max\AppData\Local\Programs\Python\Python39\lib\site-packages\websockets\protocol.py", line 827, in transfer_data
    message = await self.read_message()
  File "C:\Users\Max\AppData\Local\Programs\Python\Python39\lib\site-packages\websockets\protocol.py", line 895, in read_message
    frame = await self.read_data_frame(max_size=self.max_size)
  File "C:\Users\Max\AppData\Local\Programs\Python\Python39\lib\site-packages\websockets\protocol.py", line 971, in read_data_frame
    frame = await self.read_frame(max_size)
  File "C:\Users\Max\AppData\Local\Programs\Python\Python39\lib\site-packages\websockets\protocol.py", line 1047, in read_frame
    frame = await Frame.read(
  File "C:\Users\Max\AppData\Local\Programs\Python\Python39\lib\site-packages\websockets\framing.py", line 105, in read
    data = await reader(2)
  File "C:\Users\Max\AppData\Local\Programs\Python\Python39\lib\asyncio\streams.py", line 721, in readexactly
    raise exceptions.IncompleteReadError(incomplete, n)
asyncio.exceptions.IncompleteReadError: 0 bytes read on a total of 2 expected bytes

The above exception was the direct cause of the following exception:

Traceback (most recent call last):
  File "C:\Users\Max\Documents\Prog2\InformatiCup\spe_ed\connection.py", line 76, in <module>
    asyncio.get_event_loop().run_until_complete(connection())
  File "C:\Users\Max\AppData\Local\Programs\Python\Python39\lib\asyncio\base_events.py", line 642, in run_until_complete
    return future.result()
  File "C:\Users\Max\Documents\Prog2\InformatiCup\spe_ed\connection.py", line 57, in connection
    ans = await ws.recv()
  File "C:\Users\Max\AppData\Local\Programs\Python\Python39\lib\site-packages\websockets\protocol.py", line 509, in recv
    await self.ensure_open()
  File "C:\Users\Max\AppData\Local\Programs\Python\Python39\lib\site-packages\websockets\protocol.py", line 803, in ensure_open
    raise self.connection_closed_exc()
websockets.exceptions.ConnectionClosedError: code = 1006 (connection closed abnormally [internal]), no reason


Traceback (most recent call last):
  File "/home/kevin/anaconda3/lib/python3.8/site-packages/websockets/protocol.py", line 827, in transfer_data
    message = await self.read_message()
  File "/home/kevin/anaconda3/lib/python3.8/site-packages/websockets/protocol.py", line 895, in read_message
    frame = await self.read_data_frame(max_size=self.max_size)
  File "/home/kevin/anaconda3/lib/python3.8/site-packages/websockets/protocol.py", line 971, in read_data_frame
    frame = await self.read_frame(max_size)
  File "/home/kevin/anaconda3/lib/python3.8/site-packages/websockets/protocol.py", line 1047, in read_frame
    frame = await Frame.read(
  File "/home/kevin/anaconda3/lib/python3.8/site-packages/websockets/framing.py", line 105, in read
    data = await reader(2)
  File "/home/kevin/anaconda3/lib/python3.8/asyncio/streams.py", line 723, in readexactly
    await self._wait_for_data('readexactly')
  File "/home/kevin/anaconda3/lib/python3.8/asyncio/streams.py", line 517, in _wait_for_data
    await self._waiter
  File "/home/kevin/anaconda3/lib/python3.8/asyncio/selector_events.py", line 846, in read_ready_data_received
    data = self._sock.recv(self.max_size)
ConnectionResetError: [Errno 104] Connection reset by peer

The above exception was the direct cause of the following exception:

Traceback (most recent call last):
  File "connection.py", line 75, in <module>
    asyncio.get_event_loop().run_until_complete(connection())
  File "/home/kevin/anaconda3/lib/python3.8/asyncio/base_events.py", line 616, in run_until_complete
    return future.result()
  File "connection.py", line 57, in connection
    ans = await ws.recv()
  File "/home/kevin/anaconda3/lib/python3.8/site-packages/websockets/protocol.py", line 509, in recv
    await self.ensure_open()
  File "/home/kevin/anaconda3/lib/python3.8/site-packages/websockets/protocol.py", line 803, in ensure_open
    raise self.connection_closed_exc()
websockets.exceptions.ConnectionClosedError: code = 1006 (connection closed abnormally [internal]), no reason


Traceback (most recent call last):
  File "C:\Users\Max\AppData\Local\Programs\Python\Python39\lib\site-packages\websockets\protocol.py", line 827, in transfer_data
    message = await self.read_message()
  File "C:\Users\Max\AppData\Local\Programs\Python\Python39\lib\site-packages\websockets\protocol.py", line 895, in read_message
    frame = await self.read_data_frame(max_size=self.max_size)
  File "C:\Users\Max\AppData\Local\Programs\Python\Python39\lib\site-packages\websockets\protocol.py", line 971, in read_data_frame
    frame = await self.read_frame(max_size)
  File "C:\Users\Max\AppData\Local\Programs\Python\Python39\lib\site-packages\websockets\protocol.py", line 1047, in read_frame
    frame = await Frame.read(
  File "C:\Users\Max\AppData\Local\Programs\Python\Python39\lib\site-packages\websockets\framing.py", line 133, in read
    data = await reader(length)
  File "C:\Users\Max\AppData\Local\Programs\Python\Python39\lib\asyncio\streams.py", line 723, in readexactly
    await self._wait_for_data('readexactly')
  File "C:\Users\Max\AppData\Local\Programs\Python\Python39\lib\asyncio\streams.py", line 517, in _wait_for_data
    await self._waiter
  File "C:\Users\Max\AppData\Local\Programs\Python\Python39\lib\asyncio\proactor_events.py", line 395, in _loop_writing
    self._write_fut = self._loop._proactor.send(self._sock, data)
  File "C:\Users\Max\AppData\Local\Programs\Python\Python39\lib\asyncio\windows_events.py", line 532, in send
    ov.WSASend(conn.fileno(), buf, flags)
ConnectionResetError: [WinError 10054] Eine vorhandene Verbindung wurde vom Remotehost geschlossen

The above exception was the direct cause of the following exception:

Traceback (most recent call last):
  File "C:\Users\Max\Documents\Prog2\InformatiCup\connect.py", line 76, in <module>
    asyncio.get_event_loop().run_until_complete(connection())
  File "C:\Users\Max\AppData\Local\Programs\Python\Python39\lib\asyncio\base_events.py", line 642, in run_until_complete
    return future.result()
  File "C:\Users\Max\Documents\Prog2\InformatiCup\connect.py", line 57, in connection
    ans = await ws.recv()
  File "C:\Users\Max\AppData\Local\Programs\Python\Python39\lib\site-packages\websockets\protocol.py", line 509, in recv
    await self.ensure_open()
  File "C:\Users\Max\AppData\Local\Programs\Python\Python39\lib\site-packages\websockets\protocol.py", line 803, in ensure_open
    raise self.connection_closed_exc()
websockets.exceptions.ConnectionClosedError: code = 1006 (connection closed abnormally [internal]), no reason

++++++++++++++++++++++++++++++++++++++++++++++++++++++++++++++++++++++++
(base) PS C:\Users\Maxi\PycharmProjects\spe_ed> python speed_env_luh.py
Waiting for initial state...
PRIOR game ready: TIME:  2020-12-16 12:28:06.332047
2020-12-16 12:30:53.486045: I tensorflow/core/platform/cpu_feature_guard.cc:142] This TensorFlow binary is optimized with oneAPI Deep Neural Network Library (oneDNN)to use the following CPU instructions in performance-critical operations:  AVX
To enable them in other operations, rebuild TensorFlow with the appropriate compiler flags.
Action sent:  turn_right
Action sent:  turn_right
Action sent:  speed_up
Action sent:  slow_down
Action sent:  turn_left
Action sent:  turn_left
Action sent:  turn_left
Action sent:  slow_down
Action sent:  speed_up
Action sent:  turn_right
Action sent:  speed_up
Action sent:  slow_down
Action sent:  slow_down
Action sent:  change_nothing
Action sent:  speed_up
Action sent:  slow_down
Action sent:  turn_left
Action sent:  slow_down
Action sent:  change_nothing
Action sent:  speed_up
Traceback (most recent call last):
  File "C:\Users\Maxi\miniconda3\lib\site-packages\websockets\protocol.py", line 827, in transfer_data
    message = await self.read_message()
  File "C:\Users\Maxi\miniconda3\lib\site-packages\websockets\protocol.py", line 895, in read_message
    frame = await self.read_data_frame(max_size=self.max_size)
  File "C:\Users\Maxi\miniconda3\lib\site-packages\websockets\protocol.py", line 971, in read_data_frame
    frame = await self.read_frame(max_size)
  File "C:\Users\Maxi\miniconda3\lib\site-packages\websockets\protocol.py", line 1047, in read_frame
    frame = await Frame.read(
  File "C:\Users\Maxi\miniconda3\lib\site-packages\websockets\framing.py", line 133, in read
    data = await reader(length)
  File "C:\Users\Maxi\miniconda3\lib\asyncio\streams.py", line 723, in readexactly
    await self._wait_for_data('readexactly')
  File "C:\Users\Maxi\miniconda3\lib\asyncio\streams.py", line 517, in _wait_for_data
    await self._waiter
  File "C:\Users\Maxi\miniconda3\lib\asyncio\proactor_events.py", line 395, in _loop_writing
    self._write_fut = self._loop._proactor.send(self._sock, data)
  File "C:\Users\Maxi\miniconda3\lib\asyncio\windows_events.py", line 528, in send
    ov.WSASend(conn.fileno(), buf, flags)
ConnectionAbortedError: [WinError 10053] Eine bestehende Verbindung wurde softwaregesteuert
durch den Hostcomputer abgebrochen

The above exception was the direct cause of the following exception:

Traceback (most recent call last):
  File "speed_env_luh.py", line 670, in <module>
    main()
  File "speed_env_luh.py", line 665, in main
    asyncio.get_event_loop().run_until_complete(connection())
  File "C:\Users\Maxi\miniconda3\lib\asyncio\base_events.py", line 616, in run_until_complete
    return future.result()
  File "speed_env_luh.py", line 562, in connection
    ans = await ws.recv()
  File "C:\Users\Maxi\miniconda3\lib\site-packages\websockets\protocol.py", line 509, in recv
    await self.ensure_open()
  File "C:\Users\Maxi\miniconda3\lib\site-packages\websockets\protocol.py", line 803, in ensure_open
    raise self.connection_closed_exc()
websockets.exceptions.ConnectionClosedError: code = 1006 (connection closed abnormally [internal]), no reason
++++++++++++++++++++++++++++++++++++++++++++++++++++++++++++++++++++++++

Action sent:  change_nothing
Action sent:  slow_down
Action sent:  slow_down
Action sent:  turn_right
Traceback (most recent call last):
  File "speed_env_luh.py", line 666, in <module>
    main()
  File "speed_env_luh.py", line 661, in main
    asyncio.get_event_loop().run_until_complete(connection())
  File "C:\Users\Maxi\miniconda3\lib\asyncio\base_events.py", line 616, in run_until_complete
    return future.result()
  File "speed_env_luh.py", line 641, in connection
    await ws.send(action_json)
  File "C:\Users\Maxi\miniconda3\lib\site-packages\websockets\protocol.py", line 555, in send
    await self.ensure_open()
  File "C:\Users\Maxi\miniconda3\lib\site-packages\websockets\protocol.py", line 803, in ensure_open
    raise self.connection_closed_exc()
websockets.exceptions.ConnectionClosedError: code = 1006 (connection closed abnormally [internal]), no reason

++++++++++++++++++++++++++++++++++++++++++++++++++++++++++++++++++++++++